Workbook

Sheet Cover
A1: BLOOM ENERGY (NYSE: BE) INITIATION MODEL
A2: Tommy Lau | Bloom Energy (NYSE: BE) | 6 October 2026 | Non-GAAP basis | Personal research, not investment advice.
A4: Item | B4: Value | C4: Note
A5: Call | B5: =Valuation!$B$12 | C5: Tommy Lau's call, published 6 Oct 2026.
A6: Conviction | B6: Medium | C6: Judgement, not formula.
A7: Reference price, US$ | B7: =Assumptions!$B$7 | C7: NYSE close, 5 October 2026.
A8: Base value, US$ | B8: =Valuation!$B$7 | C8: 40x 2028E EPS.
A9: Base value against the price | B9: =Valuation!$B$9
A10: Probability-weighted value, US$ | B10: =Valuation!$B$10 | C10: 25 / 50 / 25 bear / base / bull.
A11: 2026E / 2027E / 2028E EPS, US$ | B11: =TEXT(Financials!D19,"0.00")&" / "&TEXT(Financials!E19,"0.00")&" / "&TEXT(Financials!F19,"0.00") | C11: Own estimates, non-GAAP, fully diluted.
A12: Horizon | B12: 12 months, to October 2027
A13: Wrong if | B13: See note | C13: Bloom's 2027 revenue of US$7bn or more with non-GAAP gross margin of 36% or more; or the shares close above US$360 or below US$200 by October 2027.
A14: Revisit if | B14: See note | C14: A price above about US$322 (consider short) or below about US$210 (consider long); a 2027 guide below 40% growth; or product gross margin of 38% or more in two quarters running.
A17: Tabs
A18: Assumptions | B18: Every input, with its source. Change the yellow cells to move the value.
A19: Dilution | B19: Shares outstanding, convertible notes, staff awards, the Oracle warrant; the fully diluted count.
A20: Quarterly | B20: Q1 2024 to Q2 2026 reported, my Q3 and Q4 2026; product and service margins, related-party sales.
A21: Financials | B21: 2024A to 2028E: revenue, margins, operating income, net profit, EPS, P/E, megawatt-equivalents.
A22: Scenarios | B22: Bear / base / bull and the probability-weighted value.
A23: Capacity | B23: Revenue converted to gigawatts at AEP's price, against the factory.
A24: Valuation | B24: Base value, market value, multiples, what the price needs.
A25: Sensitivity | B25: 2028E EPS against multiple.
A26: Peers | B26: Forward multiples used to set the base multiple.
A27: Sources | B27: Every source used.
A29: Colour key: blue = hardcoded input; yellow fill = my own assumption; green = link to another tab; black = formula.
A30: Companion note: 2026-10-06_BloomEnergy_Initiation.pdf. Personal research, not investment advice.

Sheet Assumptions
A1: ASSUMPTIONS AND INPUTS
A2: Tommy Lau | Bloom Energy (NYSE: BE) | 6 October 2026 | Non-GAAP basis | Personal research, not investment advice.
A3: Blue = hardcoded input. Yellow fill = my own assumption (change these to move the value). Green = link to another tab. Black = formula. US$ billion unless stated; per-share figures in US$. Non-GAAP basis unless marked GAAP.
A5: Input | B5: Value | C5: Unit | D5: Source / note
A6: MARKET (retrieved 6 October 2026)
A7: Share price (NYSE: BE) | B7: 286.65 | C7: US$ | D7: NYSE close, 5 October 2026. Yahoo Finance.
A8: 52-week high (intraday, 25 June 2026) | B8: 351.28 | C8: US$ | D8: Yahoo Finance.
A9: Highest close (22 June 2026) | B9: 345.85 | C9: US$ | D9: Yahoo Finance.
A10: Month-end close, 31 Dec 2025 | B10: 86.89 | C10: US$ | D10: Yahoo Finance.
A11: Shares outstanding, 22 Jul 2026 | B11: 0.294527 | C11: bn | D11: 10-Q cover: 294,527,346.
A12: Cash and equivalents, 30 Jun 2026 | B12: 2.667 | C12: US$bn | D12: Q2 2026 release: 2,666.9m (excludes restricted cash).
A13: Debt principal, 30 Jun 2026 | B13: 2.53 | C13: US$bn | D13: 10-Q: 0% 2030 notes 2,500.0m; Green 2029 27.0m; Green 2028 0.8m (redeemed 10 Jul); Korea loan 2.6m.
A14: Financing obligations, 30 Jun 2026 (not in net cash) | B14: 0.206 | C14: US$bn | D14: Old sale-leaseback structures: 62.0m current + 144.4m long-term.
A15: 2026 consensus EPS | B15: 2.71 | C15: US$ | D15: stockanalysis.com, 25 analysts, retrieved 6 October 2026.
A16: 2027 consensus EPS | B16: 4.33 | C16: US$ | D16: Nasdaq.com (Zacks), 6 estimates.
A17: 2028 consensus EPS | B17: 7 | C17: US$ | D17: Nasdaq.com (Zacks), 2 estimates.
A18: Q3 2026 consensus EPS | B18: 0.57 | C18: US$ | D18: Nasdaq.com (Zacks), 4 estimates.
... A20: Average analyst target | B20: 282.82 | C20: US$ | D20: stockanalysis.com, 29 analysts; median US$303, range US$97 to 390.
A21: REPORTED (Bloom releases, Form 10-K, Form 10-Q)
A22: Revenue, H1 2026 | B22: 1.8164 | C22: US$bn | D22: Q2 2026 release: 751.1 + 1,065.4.
A23: Non-GAAP gross profit, H1 2026 | B23: 0.6017 | C23: US$bn | D23: Q2 2026 release: 236.3 + 365.4.
A24: Non-GAAP operating expenses, H1 2026 | B24: 0.2323 | C24: US$bn | D24: Q2 2026 release: 106.6 + 125.7.
A25: Non-GAAP operating income, H1 2026 | B25: 0.3694 | C25: US$bn | D25: Q2 2026 release: 129.7 + 239.6.
A26: Adjusted net profit, H1 2026 | B26: 0.3863 | C26: US$bn | D26: Q2 2026 release: 138.1 + 248.2.
A27: Non-GAAP diluted EPS, H1 2026 | B27: 1.22 | C27: US$ | D27: Q2 2026 release: 0.44 + 0.78.
A28: 2026 revenue guide, low | B28: 3.9 | C28: US$bn | D28: Release of 28 July 2026.
A29: 2026 revenue guide, high | B29: 4.2 | C29: US$bn | D29: Same.
A30: 2026 non-GAAP EPS guide, low | B30: 2.55 | C30: US$ | D30: Same.
A31: 2026 non-GAAP EPS guide, high | B31: 2.85 | C31: US$ | D31: Same.
A32: 2026 non-GAAP operating income guide, low | B32: 0.8 | C32: US$bn | D32: Same.
A33: 2026 non-GAAP operating income guide, high | B33: 0.9 | C33: US$bn | D33: Same.
... A38: Fremont annual capacity, end-2026 plan | B38: 2 | C38: GW | D38: Form 10-K for 2025: doubling from 1 GW to 2 GW by end of 2026.
A39: MY ASSUMPTIONS
A40: Revenue, Q3 2026 | B40: 1.05 | C40: US$bn | D40: MINE. Guide implies H2 of US$2.08 to 2.38bn.
A41: Revenue, Q4 2026 | B41: 1.2 | C41: US$bn | D41: MINE.
A42: Non-GAAP gross margin, Q3 2026 | B42: 0.345 | C42: % | D42: MINE. Guide about 34% for the year; H1 33.1%.
A43: Non-GAAP gross margin, Q4 2026 | B43: 0.345 | C43: % | D43: MINE.
A44: Non-GAAP operating expenses, Q3 2026 | B44: 0.135 | C44: US$bn | D44: MINE. Q2: 0.126.
A45: Non-GAAP operating expenses, Q4 2026 | B45: 0.145 | C45: US$bn | D45: MINE.
A46: Adjusted net profit less non-GAAP operating income, per quarter, before tax | B46: 0.008 | C46: US$bn | D46: MINE. Q1 and Q2 2026: about 0.008 (net interest income).
...

Sheet Dilution
A1: SHARE COUNT, COUNTED FULLY DILUTED
A2: Tommy Lau | Bloom Energy (NYSE: BE) | 6 October 2026 | Non-GAAP basis | Personal research, not investment advice.
A4: Line | B4: Value | C4: Working / note
A5: Shares outstanding, 22 Jul 2026, bn | B5: =Assumptions!$B$11 | C5: 10-Q cover.
A6: 0% notes due Nov 2030, principal, US$bn | B6: 2.5 | C6: Issued 4 Nov 2025.
A7: Conversion rate, shares per US$1,000 | B7: 5.129 | C7: Conversion price US$194.97.
A8: Shares on conversion, bn | B8: =B6*B7/1000 | C8: Up to 19.554m after a make-whole fundamental change.
A9: 3.0% Green notes due Jun 2029, principal outstanding, US$bn | B9: 0.026971 | C9: After US$147m of Green notes converted in H1 2026.
A10: Conversion rate, shares per US$1,000 | B10: 47.9795 | C10: Conversion price US$20.84.
A11: Shares on conversion, bn | B11: =B9*B10/1000
A12: Stock options and awards in the Q2 2026 diluted count, bn | B12: 0.016022 | C12: 10-Q Note 15, treasury stock method.
A13: Fully diluted shares, bn | B13: =B5+B8+B11+B12 | C13: Used for H2 2026 EPS; Q2 2026 reported diluted: 323.3m.
A14: Note conversions against shares outstanding | B14: =(B8+B11)/B5
A16: Early-conversion trigger price (130% of US$194.97), US$ | B16: =1.3*194.97 | C16: 20 of the last 30 trading days of a quarter.
A17: Q3 2026 trading days of the last 30 closing above it | B17: 17 | C17: My count of Yahoo Finance closes; 20 needed. Not verified against the trustee.
A18: Stock-based compensation, Q2 2026, US$bn | B18: =Assumptions!$B$34 | C18: Excluded from non-GAAP figures.
A19: Against non-GAAP operating income, Q2 2026 | B19: =B18/Assumptions!$B$35
A20: Oracle warrant: shares issued on exercise, m | B20: 2.154231 | C20: 1,905,433 on net exercise plus 248,798 inducement shares, 1 May 2026.
A21: Oracle warrant: value to come off revenue, US$bn | B21: 0.3244 | C21: Amortised as Oracle's systems are delivered; US$17.9m so far.

Sheet Quarterly
A1: QUARTERLY HISTORY, Q1 2024 TO Q2 2026, AND MY Q3 / Q4 2026
A2: Tommy Lau | Bloom Energy (NYSE: BE) | 6 October 2026 | Non-GAAP basis | Personal research, not investment advice.
A4: US$ billion unless stated | B4: Q1 24 | C4: Q2 24 | D4: Q3 24 | E4: Q4 24 | F4: Q1 25 | G4: Q2 25 | H4: Q3 25 | I4: Q4 25 | J4: Q1 26 | K4: Q2 26 | L4: Q3 26E | M4: Q4 26E
A5: Revenue | B5: 0.2353 | C5: 0.3358 | D5: 0.3304 | E5: 0.5724 | F5: 0.326 | G5: 0.4012 | H5: 0.519 | I5: 0.7777 | J5: 0.7511 | K5: 1.0654 | L5: =Assumptions!$B$40 | M5: =Assumptions!$B$41
A6: Product revenue | B6: 0.1534 | C6: 0.2263 | D6: 0.2338 | E6: 0.4717 | F6: 0.2119 | G6: 0.2966 | H6: 0.3843 | I6: 0.6385 | J6: 0.6533 | K6: 0.9354
A7: Product cost of revenue | B7: 0.1158 | C7: 0.1613 | D7: 0.1551 | E7: 0.2536 | F7: 0.1396 | G7: 0.1987 | H7: 0.2498 | I7: 0.4047 | J7: 0.4292 | K7: 0.594
A8: Product gross margin, GAAP (derived) | B8: =(B6-B7)/B6 | C8: =(C6-C7)/C6 | D8: =(D6-D7)/D6 | E8: =(E6-E7)/E6 | F8: =(F6-F7)/F6 | G8: =(G6-G7)/G6 | H8: =(H6-H7)/H6 | I8: =(I6-I7)/I6 | ... K8: =(K6-K7)/K6
A9: Service revenue | B9: 0.0565 | C9: 0.0525 | D9: 0.0508 | E9: 0.0538 | F9: 0.0535 | G9: 0.0544 | H9: 0.0586 | I9: 0.0617 | J9: 0.0619 | K9: 0.069
A10: Service cost of revenue | B10: 0.0565 | C10: 0.0524 | D10: 0.0514 | E10: 0.0547 | F10: 0.0529 | G10: 0.0494 | H10: 0.0518 | I10: 0.0513 | J10: 0.0537 | K10: 0.0561
A11: Service gross margin, GAAP (derived) | B11: =(B9-B10)/B9 | C11: =(C9-C10)/C9 | D11: =(D9-D10)/D9 | E11: =(E9-E10)/E9 | F11: =(F9-F10)/F9 | G11: =(G9-G10)/G9 | H11: =(H9-H10)/H9 | I11: =(I9-I10)/I9 | ... K11: =(K9-K10)/K9
A12: Gross margin, GAAP (reported) | B12: 0.162 | C12: 0.204 | D12: 0.238 | E12: 0.383 | F12: 0.272 | G12: 0.267 | H12: 0.292 | I12: 0.308 | J12: 0.3 | K12: 0.334
A13: Gross margin, non-GAAP (reported; Q3 / Q4 26 mine) | B13: 0.175 | C13: 0.218 | D13: 0.252 | E13: 0.393 | F13: 0.287 | G13: 0.282 | H13: 0.304 | I13: 0.319 | J13: 0.315 | K13: 0.343 | L13: =Assumptions!$B$42 | M13: =Assumptions!$B$43
A14: Non-GAAP operating income (Q3 / Q4 26 mine) | L14: =L5*L13-Assumptions!$B$44 | M14: =M5*M13-Assumptions!$B$45
A15: Non-GAAP diluted EPS, US$ (reported; Q3 / Q4 26 mine) | B15: -0.17 | C15: -0.06 | D15: -0.01 | E15: 0.43 | F15: 0.03 | G15: 0.1 | H15: 0.15 | I15: 0.45 | J15: 0.44 | K15: 0.78 | L15: =(L14+Assumptions!$B$46)*(1-Assumptions!$B$48)/Dilution!$B$13 | M15: =(M14+Assumptions!$B$46)*(1-Assumptions!$B$48)/Dilution!$B$13
A16: Revenue to related parties | B16: 0.1222 | C16: 0.0868 | D16: 0.1266 | E16: 0.003 | F16: 0.0028 | G16: 0.0271 | H16: 0.288 | I16: 0.5742 | J16: 0.3733 | K16: 0.0028
A17: Related-party share of revenue (derived) | B17: =B16/B5 | C17: =C16/C5 | D17: =D16/D5 | E17: =E16/E5 | F17: =F16/F5 | G17: =G16/G5 | H17: =H16/H5 | I17: =I16/I5 | ... K17: =K16/K5
A19: Checks
A20: Trailing four quarters non-GAAP EPS to Q2 26 | B20: =SUM(H15:K15)
A21: Product gross margin, H1 2026 | B21: =(J6+K6-J7-K7)/(J6+K6)
A22: Revenue, H1 2026 against H1 2024 (times) | B22: =(J5+K5)/(B5+C5)
A23: Revenue growth, Q2 2026 on Q2 2025 | B23: =K5/G5-1
A24: H2 2026E revenue against the guide's implied H2 (low / high) | B24: =L5+M5 | C24: =Assumptions!$B$28-Assumptions!$B$22 | D24: =Assumptions!$B$29-Assumptions!$B$22
A26: Source: Bloom results releases (Exhibit 99.1 to Form 8-K): Q2 2024 (with Q1 2024), Q2 2025 (with Q1 2025), Q3 2025 (with Q3 2024), Q4 2025 (with Q4 2024), Q2 2026 (with Q1 2026).
A27: Q3 26E and Q4 26E are my estimates: EPS = (revenue x gross margin - operating costs + other income) x (1 - tax) / fully diluted shares (Dilution tab).

Sheet Financials
A1: FINANCIAL SUMMARY AND FORECASTS (US$ billion unless stated, non-GAAP basis)
A2: Tommy Lau | Bloom Energy (NYSE: BE) | 6 October 2026 | Non-GAAP basis | Personal research, not investment advice.
B4: 2024A | C4: 2025A | D4: 2026E* | E4: 2027E* | F4: 2028E*
A5: Revenue | B5: 1.4739 | C5: 2.024 | D5: =Assumptions!$B$22+Quarterly!L5+Quarterly!M5 | E5: =D5*(1+Scenarios!B6) | F5: =E5*(1+Scenarios!C6)
A6: Revenue growth | C6: =C5/B5-1 | D6: =D5/C5-1 | E6: =E5/D5-1 | F6: =F5/E5-1
A7: Product revenue | B7: 1.0852 | C7: 1.5313 | D7: =Quarterly!J6+Quarterly!K6
A8: Product cost of revenue | B8: 0.6858 | C8: 0.9928 | D8: =Quarterly!J7+Quarterly!K7
A9: Product gross margin, GAAP (2026: H1) | B9: =(B7-B8)/B7 | C9: =(C7-C8)/C7 | D9: =(D7-D8)/D7
A10: Gross profit | B10: =B5*0.287 | C10: =C5*0.303 | D10: =Assumptions!$B$23+Quarterly!L5*Quarterly!L13+Quarterly!M5*Quarterly!M13 | E10: =E5*Scenarios!D6 | F10: =F5*Scenarios!E6
A11: Gross margin | B11: =B10/B5 | C11: =C10/C5 | D11: =D10/D5 | E11: =E10/E5 | F11: =F10/F5
A12: Operating expenses | B12: =B10-B13 | C12: =C10-C13 | D12: =Assumptions!$B$24+Assumptions!$B$44+Assumptions!$B$45 | E12: =Scenarios!F6 | F12: =Scenarios!G6
A13: Operating income | B13: 0.1076 | C13: 0.221 | D13: =D10-D12 | E13: =E10-E12 | F13: =F10-F12
A14: Operating margin | B14: =B13/B5 | C14: =C13/C5 | D14: =D13/D5 | E14: =E13/E5 | F14: =F13/F5
A15: Other income less operating income gap (2026: H1 actual plus H2) | D15: =(Assumptions!$B$26-Assumptions!$B$25)+2*Assumptions!$B$46 | E15: =Assumptions!$B$47 | F15: =Assumptions!$B$47
A16: Tax rate (2026: H2) | D16: =Assumptions!$B$48 | E16: =Assumptions!$B$49 | F16: =Assumptions!$B$50
A17: Adjusted net profit | D17: =Assumptions!$B$26+(Quarterly!L14+Assumptions!$B$46)*(1-D16)+(Quarterly!M14+Assumptions!$B$46)*(1-D16) | E17: =(E13+E15)*(1-E16) | F17: =(F13+F15)*(1-F16)
A18: Fully diluted shares, bn | D18: =Dilution!$B$13 | E18: =D18*(1+Assumptions!$B$51) | F18: =E18*(1+Assumptions!$B$51)
A19: Diluted EPS, US$ | B19: 0.28 | C19: 0.76 | D19: =Assumptions!$B$27+Quarterly!L15+Quarterly!M15 | E19: =E17/E18 | F19: =F17/F18
A20: EPS growth | C20: =C19/B19-1 | D20: =D19/C19-1 | E20: =E19/D19-1 | F20: =F19/E19-1
A21: P/E at reference price | B21: =Assumptions!$B$7/B19 | C21: =Assumptions!$B$7/C19 | D21: =Assumptions!$B$7/D19 | E21: =Assumptions!$B$7/E19 | F21: =Assumptions!$B$7/F19
A22: Consensus EPS, US$ | D22: =Assumptions!$B$15 | E22: =Assumptions!$B$16 | F22: =Assumptions!$B$17
A23: Mine against consensus | D23: =D19/D22-1 | E23: =E19/E22-1 | F23: =F19/F22-1
A24: Product megawatt-equivalents, GW (derived) | D24: =D5*Capacity!$B$7/Capacity!$B$6 | E24: =E5*Capacity!$B$7/Capacity!$B$6 | F24: =F5*Capacity!$B$7/Capacity!$B$6
A26: *2026E to 2028E are my own estimates. 2026E = reported H1 plus my Q3 and Q4 (Quarterly tab). 2027E and 2028E use the base case on the Scenarios tab (row 6).
A27: 2024A and 2025A gross profit use the reported non-GAAP gross margins (28.7%, 30.3%); operating income and EPS as reported in the Q4 2025 release.
A28: Note check: 2026E revenue 4.07, EPS 2.78; 2027E 6.30, 4.43; 2028E 8.70, 6.03.

Sheet Scenarios
A1: THREE CASES, TWELVE MONTHS OUT
A2: Tommy Lau | Bloom Energy (NYSE: BE) | 6 October 2026 | Non-GAAP basis | Personal research, not investment advice.
A4: Case | B4: Growth 27 | C4: Growth 28 | D4: GM 27 | E4: GM 28 | F4: Opex 27 | G4: Opex 28 | H4: 2027 revenue | I4: 2028 revenue | J4: 2028 op. income | K4: 2028 net profit | L4: 2028 EPS | M4: Multiple | N4: Value, US$ | O4: vs price | P4: 2028 GW
A5: Bear | B5: 0.3 | C5: 0.12 | D5: 0.33 | E5: 0.32 | F5: 0.58 | G5: 0.62 | H5: =Financials!$D$5*(1+B5) | I5: =H5*(1+C5) | J5: =I5*E5-G5 | K5: =(J5+Assumptions!$B$47)*(1-Assumptions!$B$50) | L5: =K5/Financials!$F$18 | M5: 25 | N5: =L5*M5 | O5: =N5/Assumptions!$B$7-1 | P5: =I5*Capacity!$B$7/Capacity!$B$6
A6: Base | B6: 0.55 | C6: 0.38 | D6: 0.35 | E6: 0.355 | F6: 0.62 | G6: 0.75 | H6: =Financials!$D$5*(1+B6) | I6: =H6*(1+C6) | J6: =I6*E6-G6 | K6: =(J6+Assumptions!$B$47)*(1-Assumptions!$B$50) | L6: =K6/Financials!$F$18 | M6: =Assumptions!$B$53 | N6: =L6*M6 | O6: =N6/Assumptions!$B$7-1 | P6: =I6*Capacity!$B$7/Capacity!$B$6
A7: Bull | B7: 0.7 | C7: 0.5 | D7: 0.365 | E7: 0.375 | F7: 0.66 | G7: 0.82 | H7: =Financials!$D$5*(1+B7) | I7: =H7*(1+C7) | J7: =I7*E7-G7 | K7: =(J7+Assumptions!$B$47)*(1-Assumptions!$B$50) | L7: =K7/Financials!$F$18 | M7: 50 | N7: =L7*M7 | O7: =N7/Assumptions!$B$7-1 | P7: =I7*Capacity!$B$7/Capacity!$B$6
B9: Bear | C9: Base | D9: Bull
A10: Probability | B10: 0.25 | C10: 0.5 | D10: 0.25 | E10: =SUM(B10:D10) | F10: must be 100%
A12: Probability-weighted value, US$ | N12: =B10*N5+C10*N6+D10*N7 | O12: =N12/Assumptions!$B$7-1
A14: All cases start from my 2026E and use 2028 fully diluted shares from the Financials tab. Gross margin is non-GAAP; Opex is non-GAAP operating costs, US$bn.
A15: Bear: faster grid connections and more turbine supply narrow the window Bloom sells into. Bull: Oracle's 2.8 GW and Brookfield's US$25bn fill, Fremont expands fast.
A16: The base row (6) drives the Financials tab for 2027E and 2028E.

Sheet Capacity
A1: THE FACTORY IS THE CEILING: REVENUE CONVERTED TO GIGAWATTS (DERIVED)
A2: Tommy Lau | Bloom Energy (NYSE: BE) | 6 October 2026 | Non-GAAP basis | Personal research, not investment advice.
A4: Line | B4: Value | C4: Working / note
A5: AEP order, US$bn | B5: =Assumptions!$B$36 | C5: Reported 8 January 2026.
A6: Price per megawatt, US$m | B6: =Assumptions!$B$36/Assumptions!$B$37 | C6: My unit for converting revenue to megawatts. Bloom does not report MW shipped.
A7: Product share of revenue | B7: =Assumptions!$B$52 | C7: H1 2026.
A8: 2026E, GW | B8: =Financials!D24
A9: 2027E, GW | B9: =Financials!E24
A10: 2028E base, GW | B10: =Financials!F24
A11: Fremont annual capacity by end 2026, GW | B11: =Assumptions!$B$38 | C11: Site room for about 5 GW (10-K).
A12: Revenue a 2 GW factory supports at that price, US$bn | B12: =B11*B6/B7
A13: 2028 GW the price needs (Valuation tab) | B13: =Valuation!B29

Sheet Valuation
A1: VALUATION: 40x 2028E EPS, TWELVE MONTHS OUT
A2: Tommy Lau | Bloom Energy (NYSE: BE) | 6 October 2026 | Non-GAAP basis | Personal research, not investment advice.
A4: Line | B4: Value | C4: Working / note
A5: 2028E diluted EPS, US$ | B5: =Financials!F19 | C5: The market will be pricing 2028 by October 2027.
A6: Base multiple, x | B6: =Assumptions!$B$53 | C6: Assumptions tab.
A7: Base-case value per share, US$ | B7: =B5*B6 | C7: EPS x multiple.
A8: Reference price, US$ | B8: =Assumptions!$B$7 | C8: NYSE close, 5 October 2026.
A9: Base value against the price | B9: =B7/B8-1
A10: Probability-weighted value, US$ | B10: =Scenarios!N12 | C10: Scenarios tab.
A11: Rule on value alone (15% either side) | B11: =IF(B9>0.15,"LONG",IF(B9<-0.15,"SHORT","NO CALL")) | C11: Mechanical only. The call below is judgement.
A12: CALL | B12: NO CALL | C12: No call, leaning short: the base is only just outside the band and the stock moves 25% on one print.
A13: Market value on shares outstanding, US$bn | B13: =Assumptions!$B$7*Assumptions!$B$11
A14: Net cash, US$bn | B14: =Assumptions!$B$12-Assumptions!$B$13 | C14: 30 June 2026; excludes US$0.21bn of financing obligations.
A15: Enterprise value, US$bn | B15: =B13-B14
A16: Change since 31 Dec 2025 | B16: =Assumptions!$B$7/Assumptions!$B$10-1
A17: Price below the highest close | B17: =1-Assumptions!$B$7/Assumptions!$B$9
A18: P/E on my 2026E | B18: =Financials!D21
A19: P/E on my 2027E | B19: =Financials!E21
A20: P/E on my 2028E | B20: =Financials!F21
A21: P/E on the 2026 EPS guide midpoint | B21: =Assumptions!$B$7/((Assumptions!$B$30+Assumptions!$B$31)/2)
A22: P/E on the 2028 consensus | B22: =Assumptions!$B$7/Assumptions!$B$17 | C22: Nasdaq.com (Zacks), 2 estimates.
A23: P/E on trailing four quarters EPS | B23: =Assumptions!$B$7/Quarterly!B20
A25: 2028 EPS the price needs at the base multiple, US$ | B25: =Assumptions!$B$7/Assumptions!$B$53 | C25: What the market prices in.
A26: 2028 operating income that needs, US$bn | B26: =B25*Financials!F18/(1-Assumptions!$B$50)-Assumptions!$B$47
A27: 2028 revenue that needs at base margin and costs, US$bn | B27: =(B26+Scenarios!G6)/Scenarios!E6 | C27: Against my base US$8.70bn.
A28: That against my 2028E base revenue | B28: =B27/Financials!F5
A29: 2028 GW that needs (derived) | B29: =B27*Capacity!B7/Capacity!B6 | C29: Against 2 GW of planned factory capacity.
A30: Price that puts the base case 15% above (revisit as long) | B30: =B7/1.15
A31: Price that puts the base case 25% below (revisit as short) | B31: =B7/0.75

Sheet Sensitivity
A1: VALUE PER SHARE: 2028E EPS AGAINST MULTIPLE (US$)
A2: Tommy Lau | Bloom Energy (NYSE: BE) | 6 October 2026 | Non-GAAP basis | Personal research, not investment advice.
A4: 2028 EPS \ multiple | B4: 30 | C4: =Assumptions!$B$53 | D4: 50
A5: 4.5 | B5: =$A5*B$4 | C5: =$A5*C$4 | D5: =$A5*D$4
A6: =Financials!F19 | B6: =$A6*B$4 | C6: =$A6*C$4 | D6: =$A6*D$4
A7: 7.5 | B7: =$A7*B$4 | C7: =$A7*C$4 | D7: =$A7*D$4
A9: Cells above the reference price | B9: =COUNTIF(B5:D7,">"&Assumptions!$B$7) | C9: of 9
A11: Middle row links to the model's 2028E EPS and the middle column to the base multiple.

Sheet Peers
A1: PEER MULTIPLES (FORWARD P/E, stockanalysis.com, 6 OCTOBER 2026)
A2: Tommy Lau | Bloom Energy (NYSE: BE) | 6 October 2026 | Non-GAAP basis | Personal research, not investment advice.
A4: Company | B4: Ticker | C4: Forward P/E | D4: What they make
A5: Bloom Energy | B5: NYSE: BE | C5: =Assumptions!$B$19 | D5: Solid oxide fuel cell systems for on-site power, and their maintenance
A6: GE Vernova | B6: NYSE: GEV | C6: 47.34 | D6: Gas turbines, grid equipment and wind turbines
A7: Vertiv | B7: NYSE: VRT | C7: 31.93 | D7: Power and cooling equipment for data centres
A8: Caterpillar | B8: NYSE: CAT | C8: 29.42 | D8: Gas and diesel engine generators, plus construction and mining machines
A9: Siemens Energy | B9: Xetra: ENR | C9: 24.48 | D9: Gas turbines, grid equipment and wind turbines
A10: Cummins | B10: NYSE: CMI | C10: 15.94 | D10: Engines and generator sets
A11: FuelCell Energy | B11: Nasdaq: FCEL | C11: n/m | D11: Carbonate and solid oxide fuel cells; loss-making, no forward P/E
A13: Median, power equipment peers (GE Vernova to Cummins) | C13: =MEDIAN(C6:C10)
A15: Siemens Energy on its Frankfurt listing. FuelCell Energy is loss-making. Multiples only, to set the base multiple.
A16: No view on the peers' shares is expressed.

Sheet Sources
A1: SOURCES
A2: Tommy Lau | Bloom Energy (NYSE: BE) | 6 October 2026 | Non-GAAP basis | Personal research, not investment advice.
A4: No. | B4: Source and what it supports
A5: 1 | B5: Bloom results releases (Exhibit 99.1 to Form 8-K): Q2 2024, Q2 2025, Q3 2025, Q4 2025 (5 February 2026) and Q2 2026 (28 July 2026), with their comparative quarters: revenue and cost by line, GAAP and non-GAAP margins, operating income, EPS, related-party revenue, guidance, backlog.
A6: 2 | B6: Bloom Form 10-K for 2025: backlog definitions; service contracts of 5 to 20 years, terminable for convenience each year; 1 GW to 2 GW capacity plan; grid queues and the SPP 90-day study route approved by FERC in January 2026.
A7: 3 | B7: Bloom Form 10-Q for Q2 2026: debt table and note terms, Green note conversions, Oracle warrant (3,531,073 at US$113.28; exercised 1 May 2026), EPS reconciliation, Brookfield joint ventures, customer concentration, the 8 July 2026 short report.
A8: 4 | B8: Bloom announcements: Oracle, up to 2.8 GW with 1.2 GW contracted (13 April 2026); Brookfield framework to US$25bn (30 June 2026); Power Connect (19 August 2026); Q3 2025 results date notice (9 October 2025).
A9: 5 | B9: AEP exercise of most of its 900 MW option, about US$2.65bn, as reported on 8 January 2026.
A10: 6 | B10: Yahoo Finance chart API, retrieved 6 October 2026: month-end and daily closes, 52-week range.
A11: 7 | B11: stockanalysis.com, retrieved 6 October 2026: 2026 consensus EPS and revenue, average target, forward P/E for Bloom and peers. Nasdaq.com (Zacks): 2027 and 2028 consensus EPS, Q3 2026 consensus.
A12: 8 | B12: The Physical Layer, 'Bloom Energy is not selling electricity. It is selling time.', 24 September 2026: https://thephysicallayer.fyi/journal/the-product-is-time/
A13: 9 | B13: Estimates for 2026 to 2028 are the author's own. Personal research, not investment advice. I hold no position in Bloom Energy.
