Workbook

Sheet Cover
A1: TSMC (NYSE: TSM ADR; TWSE: 2330) INITIATION MODEL
A2: Tommy Lau | TSMC (NYSE: TSM; TWSE: 2330) | 6 October 2026 | Personal research, not investment advice.
A4: Item | B4: Value | C4: Note
A5: Call | B5: =Valuation!$B$11 | C5: Tommy Lau's call, published 6 Oct 2026.
A6: Conviction | B6: Medium | C6: Judgement, not formula.
A7: Reference price, US$ per ADR | B7: =Assumptions!$B$7 | C7: NYSE close, 5 October 2026. 1 ADR = 5 ordinary shares.
A8: Base value, US$ per ADR | B8: =Valuation!$B$7 | C8: 20x 2028E EPS.
A9: Base value against the price | B9: =Valuation!$B$9
A10: Probability-weighted value, US$ | B10: =Valuation!$B$10 | C10: 25 / 50 / 25 bear / base / bull.
A11: 2026E / 2027E / 2028E EPS per ADR, US$ | B11: =TEXT(Financials!D12,"0.00")&" / "&TEXT(Financials!E12,"0.00")&" / "&TEXT(Financials!F12,"0.00") | C11: Own estimates.
A12: Horizon | B12: 12 months, to October 2027
A13: Wrong if | B13: See note | C13: Full year 2027 revenue grows 30% or more in US dollars with an operating margin of 58% or more; or TSMC raises its through-the-cycle gross margin floor above 56%; or the ADR trades above US$560 by October 2027 without either.
A14: Revisit if | B14: See note | C14: A price below about US$400, or Q3 gross margin at or above the 67% top of the guide despite the 2nm ramp, or a raised margin floor.
A17: Tabs
A18: Assumptions | B18: Every input, with its source. Change the yellow cells to move the value.
A19: Quarterly | B19: Q1 2024 to Q2 2026 reported, my Q3 and Q4 2026; wafers, revenue per wafer, non-operating items, capex.
A20: Monthly | B20: Monthly revenue January 2025 to August 2026 and the Q3 2026 track against the guide.
A21: Financials | B21: 2024A to 2028E: revenue, margin, the EPS bridge per ADR, P/E.
A22: Valuation | B22: Base value, market value, ADR premium, multiples, what the price needs.
A23: Scenarios | B23: Bear / base / bull and the probability-weighted value.
A24: Sensitivity | B24: 2028E EPS against multiple.
A25: Peers | B25: Forward multiples used to set the base multiple.
A26: Sources | B26: Every source used.
A28: Colour key: blue = hardcoded input; yellow fill = my own assumption; green = link to another tab; black = formula.
A29: Companion note: 2026-10-06_TSMC_Initiation.pdf. Personal research, not investment advice.

Sheet Assumptions
A1: ASSUMPTIONS AND INPUTS
A2: Tommy Lau | TSMC (NYSE: TSM; TWSE: 2330) | 6 October 2026 | Personal research, not investment advice.
A3: Blue = hardcoded input. Yellow fill = my own assumption (change these to move the value). Green = link to another tab. Black = formula. US$ billion unless stated; per-ADR figures in US$.
A5: Input | B5: Value | C5: Unit | D5: Source / note
A6: MARKET (retrieved 6 October 2026)
A7: ADR price (NYSE: TSM) | B7: 485.8 | C7: US$ | D7: NYSE close, 5 October 2026. Yahoo Finance.
A8: ADR 52-week high (intraday) | B8: 487.47 | C8: US$ | D8: Yahoo Finance.
A9: ADR month-end close, 30 Sep 2025 | B9: 279.29 | C9: US$ | D9: Yahoo Finance.
A10: Taipei share price (2330.TW) | B10: 2585 | C10: NT$ | D10: TWSE close, 6 October 2026. Yahoo Finance.
A11: NT$ per US$ | B11: 31.746 | C11: NT$ | D11: Yahoo Finance TWD=X, 6 October 2026.
A12: Ordinary shares per ADR | B12: 5 | C12: x | D12: TSMC ADR ratio.
A13: Ordinary shares outstanding | B13: 25.932 | C13: bn | D13: 2Q26 presentation: 25,932mn units at 30 June 2026.
A14: Cash and marketable securities, 30 Jun 2026 | B14: 3518.01 | C14: NT$bn | D14: 2Q26 presentation, balance sheet.
A15: Long-term interest-bearing debts, 30 Jun 2026 | B15: 864.27 | C15: NT$bn | D15: 2Q26 presentation. Current portion not separately shown, so net cash is approximate.
A16: 2026 consensus EPS per ADR | B16: 16.56 | C16: US$ | D16: MarketBeat, retrieved 6 October 2026. Cross-check only.
A17: 2027 consensus EPS per ADR | B17: 21.33 | C17: US$ | D17: MarketBeat, retrieved 6 October 2026. Cross-check only.
A18: Forward P/E shown by stockanalysis.com | B18: 20.73 | C18: x | D18: stockanalysis.com, 6 October 2026.
A19: Average analyst ADR target | B19: 552.26 | C19: US$ | D19: stockanalysis.com, 21 analysts, 6 October 2026.
A20: REPORTED (TSMC 4Q25 presentation, 15 Jan 2026; quarterly releases)
A21: 2024 revenue | B21: 90.08 | C21: US$bn | D21: TSMC 4Q25 presentation, 2025 financial highlights.
A22: 2025 revenue | B22: 122.42 | C22: US$bn | D22: Same.
A23: 2024 gross margin | B23: 0.561 | C23: % | D23: Same.
A24: 2025 gross margin | B24: 0.599 | C24: % | D24: Same.
A25: 2024 operating margin | B25: 0.457 | C25: % | D25: Same.
A26: 2025 operating margin | B26: 0.508 | C26: % | D26: Same.
A27: 2024 EPS per ADR | B27: 7.04 | C27: US$ | D27: Sum of the four quarterly releases (US$ per ADR unit).
A28: 2025 EPS per ADR | B28: 10.65 | C28: US$ | D28: Same.
A29: 2024 EPS per share | B29: 45.25 | C29: NT$ | D29: TSMC 4Q25 presentation.
A30: 2025 EPS per share | B30: 66.25 | C30: NT$ | D30: Same.
A31: Long-term gross margin floor, through the cycle | B31: 0.56 | C31: % | D31: TSMC 4Q25 presentation: 56% and higher through the cycle.
A32: Revenue CAGR 2024 to 2029, approaching | B32: 0.25 | C32: % | D32: TSMC 4Q25 presentation, US dollar terms.
... A35: Q3 2026 guide exchange rate | B35: 32 | C35: NT$ | D35: Same.
A36: MY ASSUMPTIONS
A37: Non-operating income, % of revenue | B37: 0.025 | C37: % | D37: MINE. Q1 2026 level (NT$28.83bn on NT$1,134.10bn). Q2 2026 jump to NT$95.83bn treated as non-recurring.
A38: Tax and minorities, % of pre-tax profit | B38: 0.17 | C38: % | D38: MINE. 2025: 15.9%; first half 2026: 17.5%.
A39: Q3 2026 revenue | B39: 46.4 | C39: US$bn | D39: MINE. July and August monthly revenue already NT$982.4bn; above the guide top.
A40: Q3 2026 operating margin | B40: 0.57 | C40: % | D40: MINE. Middle of the 56 to 58% guide.
A41: Q4 2026 revenue | B41: 49 | C41: US$bn | D41: MINE. Gives 2026 growth of 40%, in line with 'slightly above 40%'.
A42: Q4 2026 operating margin | B42: 0.56 | C42: % | D42: MINE. 2nm ramp dilution of 3 to 4 points on gross margin in the second half.
A43: 2027 revenue growth | B43: 0.24 | C43: % | D43: MINE. Inside TSMC's 2024 to 2029 plan.
...

Sheet Quarterly
A1: QUARTERLY HISTORY, Q1 2024 TO Q2 2026, AND MY Q3 / Q4 2026
A2: Tommy Lau | TSMC (NYSE: TSM; TWSE: 2330) | 6 October 2026 | Personal research, not investment advice.
A4: US$ billion unless stated | B4: Q1 24 | C4: Q2 24 | D4: Q3 24 | E4: Q4 24 | F4: Q1 25 | G4: Q2 25 | H4: Q3 25 | I4: Q4 25 | J4: Q1 26 | K4: Q2 26 | L4: Q3 26E | M4: Q4 26E
A5: Revenue, US$bn | B5: 18.87 | C5: 20.82 | D5: 23.5 | E5: 26.88 | F5: 25.53 | G5: 30.07 | H5: 33.1 | I5: 33.73 | J5: 35.9 | K5: 40.2 | L5: =Assumptions!$B$39 | M5: =Assumptions!$B$41
A6: Revenue, NT$bn | B6: 592.64 | C6: 673.51 | D6: 759.69 | E6: 868.46 | F6: 839.25 | G6: 933.79 | H6: 989.92 | I6: 1046.09 | J6: 1134.1 | K6: 1270.38
A7: Revenue growth y/y, US$ (derived) | F7: =F5/B5-1 | G7: =G5/C5-1 | H7: =H5/D5-1 | I7: =I5/E5-1 | J7: =J5/F5-1 | K7: =K5/G5-1 | L7: =L5/H5-1 | M7: =M5/I5-1
A8: Gross margin | B8: 0.531 | C8: 0.532 | D8: 0.578 | E8: 0.59 | F8: 0.588 | G8: 0.586 | H8: 0.595 | I8: 0.623 | J8: 0.662 | K8: 0.677
A9: Operating margin | B9: 0.42 | C9: 0.425 | D9: 0.475 | E9: 0.49 | F9: 0.485 | G9: 0.496 | H9: 0.506 | I9: 0.54 | J9: 0.581 | K9: 0.603 | L9: =Assumptions!$B$40 | M9: =Assumptions!$B$42
A10: EPS per share, NT$ | B10: 8.7 | C10: 9.56 | D10: 12.54 | E10: 14.45 | F10: 13.94 | G10: 15.36 | H10: 17.44 | I10: 19.5 | J10: 22.08 | K10: 27.25
A11: EPS per ADR, US$ (reported; Q3 / Q4 26 mine) | B11: 1.38 | C11: 1.48 | D11: 1.94 | E11: 2.24 | F11: 2.12 | G11: 2.47 | H11: 2.92 | I11: 3.14 | J11: 3.49 | K11: 4.31 | L11: =L5*(L9+Assumptions!$B$37)*(1-Assumptions!$B$38)*(Assumptions!$B$12/Assumptions!$B$13) | M11: =M5*(M9+Assumptions!$B$37)*(1-Assumptions!$B$38)*(Assumptions!$B$12/Assumptions!$B$13)
A12: HPC share of revenue | B12: 0.46 | C12: 0.52 | D12: 0.51 | E12: 0.53 | F12: 0.59 | G12: 0.6 | H12: 0.57 | I12: 0.55 | J12: 0.61 | K12: 0.66
A13: 7nm and below, share of wafer revenue | B13: 0.65 | C13: 0.67 | D13: 0.69 | E13: 0.74 | F13: 0.73 | G13: 0.74 | H13: 0.74 | I13: 0.77 | J13: 0.74 | K13: 0.77
A14: Gross margin above the 56% floor, points (derived) | B14: =(B8-Assumptions!$B$31)*100 | C14: =(C8-Assumptions!$B$31)*100 | D14: =(D8-Assumptions!$B$31)*100 | E14: =(E8-Assumptions!$B$31)*100 | F14: =(F8-Assumptions!$B$31)*100 | G14: =(G8-Assumptions!$B$31)*100 | H14: =(H8-Assumptions!$B$31)*100 | I14: =(I8-Assumptions!$B$31)*100 | ... K14: =(K8-Assumptions!$B$31)*100
A16: Wafers and the second quarter
A17: Item | B17: Q2 25 | C17: Q1 26 | D17: Q2 26 | E17: Note
A18: Wafer shipments, thousand 12-inch equivalent | B18: 3718 | C18: 4174 | D18: 4336 | E18: 2Q26 presentation.
A19: Revenue per wafer, NT$ thousand (derived) | B19: =G6/B18*1000 | C19: =J6/C18*1000 | D19: =K6/D18*1000
A20: Wafers y/y, Q2 26 (derived) | B20: =D18/B18-1
A21: Revenue per wafer y/y, Q2 26 (derived) | B21: =D19/B19-1
A22: Non-operating items, NT$bn, Q1 26 / Q2 26 | B22: 28.83 | C22: 95.83
A23: Q2 26 excess non-operating, after tax, per ADR, US$ (derived) | B23: =(C22-B22)*(1-Assumptions!$B$38)/Assumptions!$B$13*Assumptions!$B$12/31.60 | E23: At the Q2 26 average rate of NT$31.60 (2Q26 presentation).
A24: Capital expenditures, NT$bn, Q1 26 / Q2 26 | B24: 350.76 | C24: 496 | D24: =B24+C24 | E24: First half total in column D.
A25: Capital expenditures, NT$bn, 2024 / 2025 | B25: 956.01 | C25: 1272.41
A27: Source: TSMC quarterly results releases and presentations on Form 6-K, 18 April 2024 to 16 July 2026. HPC share from the revenue-by-platform slides.
A28: Q3 26E and Q4 26E are my estimates; EPS per ADR = revenue x (operating margin + non-operating %) x (1 - tax) x 5 / shares.

Sheet Monthly
A1: MONTHLY REVENUE, NT$ BILLION, AND THE Q3 2026 TRACK
A2: Tommy Lau | TSMC (NYSE: TSM; TWSE: 2330) | 6 October 2026 | Personal research, not investment advice.
A4: Month | B4: Revenue, NT$bn | C4: Note
A5: Jan 25 | B5: 293.29
A6: Feb 25 | B6: 260.01
A7: Mar 25 | B7: 285.96
A8: Apr 25 | B8: 349.57
A9: May 25 | B9: 320.52
A10: Jun 25 | B10: 263.71
A11: Jul 25 | B11: 323.17
A12: Aug 25 | B12: 335.77
A13: Sep 25 | B13: 330.98
A14: Oct 25 | B14: 367.47
A15: Nov 25 | B15: 343.61
A16: Dec 25 | B16: 335
... A24: Aug 26 | B24: 514.81
A26: Q3 2026 track
A27: Jul + Aug 2026 | B27: =B23+B24 | C27: Two thirds of the quarter, reported.
A28: Q3 guide low, NT$bn at guide rate | B28: =Assumptions!$B$33*Assumptions!$B$35
A29: Q3 guide high, NT$bn at guide rate | B29: =Assumptions!$B$34*Assumptions!$B$35
A30: September needed for the low end | B30: =B28-B27
A31: September needed for the high end | B31: =B29-B27 | C31: August alone was NT$514.81bn.
A32: Monthly pace of the guide midpoint | B32: =(Assumptions!$B$33+Assumptions!$B$34)/2*Assumptions!$B$35/3 | C32: Reference line on the chart.
A33: August 2026 y/y | B33: =B24/B12-1 | C33: August 2025 in row above.
A35: Source: TSMC monthly revenue reports on Form 6-K, 10 February 2025 to 10 September 2026. September 2026 is due around 10 October (not confirmed).

Sheet Financials
A1: FINANCIAL SUMMARY AND FORECASTS (US$ billion unless stated)
A2: Tommy Lau | TSMC (NYSE: TSM; TWSE: 2330) | 6 October 2026 | Personal research, not investment advice.
B4: 2024A | C4: 2025A | D4: 2026E* | E4: 2027E* | F4: 2028E*
A5: Revenue | B5: =Assumptions!$B$21 | C5: =Assumptions!$B$22 | D5: =SUM(Quarterly!J5:M5) | E5: =D5*(1+Assumptions!$B$43) | F5: =E5*(1+Assumptions!$B$44)
A6: Revenue growth | C6: =C5/B5-1 | D6: =D5/C5-1 | E6: =E5/D5-1 | F6: =F5/E5-1
A7: Gross margin (reported; not modelled ahead) | B7: =Assumptions!$B$23 | C7: =Assumptions!$B$24
A8: Operating margin | B8: =Assumptions!$B$25 | C8: =Assumptions!$B$26 | D8: =SUMPRODUCT(Quarterly!J5:M5,Quarterly!J9:M9)/D5 | E8: =Assumptions!$B$45 | F8: =Assumptions!$B$46
A9: Operating profit | B9: =B5*B8 | C9: =C5*C8 | D9: =D5*D8 | E9: =E5*E8 | F9: =F5*F8
A10: Non-operating income | D10: =D5*Assumptions!$B$37 | E10: =E5*Assumptions!$B$37 | F10: =F5*Assumptions!$B$37
A11: Net income after tax and minorities | D11: =(D9+D10)*(1-Assumptions!$B$38) | E11: =(E9+E10)*(1-Assumptions!$B$38) | F11: =(F9+F10)*(1-Assumptions!$B$38)
A12: EPS per ADR, US$ | B12: =Assumptions!$B$27 | C12: =Assumptions!$B$28 | D12: =SUM(Quarterly!J11:M11) | E12: =E11*(Assumptions!$B$12/Assumptions!$B$13) | F12: =F11*(Assumptions!$B$12/Assumptions!$B$13)
A13: EPS growth | C13: =C12/B12-1 | D13: =D12/C12-1 | E13: =E12/D12-1 | F13: =F12/E12-1
A14: P/E at reference price | B14: =Assumptions!$B$7/B12 | C14: =Assumptions!$B$7/C12 | D14: =Assumptions!$B$7/D12 | E14: =Assumptions!$B$7/E12 | F14: =Assumptions!$B$7/F12
A17: *2026E to 2028E are my own estimates. 2026E = reported Q1 and Q2 plus my Q3 and Q4 (Quarterly tab); 2026E EPS uses reported first-half EPS per ADR (US$7.80).
A18: 2024A and 2025A operating profit are derived as revenue x margin. Net income for 2026E (row 11) is illustrative; EPS uses the quarterly build.
A19: EPS bridge 2027E and 2028E: (operating profit + non-operating income) x (1 - tax and minorities) x 5 / 25.932bn shares.
A20: Note check: 2026E revenue 171.50, EPS 16.81; 2027E 212.66, 20.25; 2028E 250.94, 23.29.

Sheet Valuation
A1: VALUATION: 20x 2028E EPS PER ADR, TWELVE MONTHS OUT
A2: Tommy Lau | TSMC (NYSE: TSM; TWSE: 2330) | 6 October 2026 | Personal research, not investment advice.
A4: Line | B4: Value | C4: Working / note
A5: 2028E EPS per ADR, US$ | B5: =Financials!F12 | C5: The market will be pricing 2028 by October 2027.
A6: Base multiple, x | B6: =Assumptions!$B$47 | C6: Assumptions tab.
A7: Base-case value per ADR, US$ | B7: =B5*B6 | C7: EPS x multiple.
A8: Reference price, US$ | B8: =Assumptions!$B$7 | C8: NYSE close, 5 October 2026.
A9: Base value against the price | B9: =B7/B8-1 | C9: Within +/- 10%: no call on value alone.
A10: Probability-weighted value, US$ | B10: =Scenarios!F11 | C10: Scenarios tab.
A11: CALL | B11: =IF(B9>0.15,"LONG",IF(B9<-0.15,"SHORT","NO CALL")) | C11: Rule of thumb: 15% either side of the price. Conviction is judgement. Tommy Lau's call, 6 Oct 2026.
A13: Market value at the ADR price, US$bn | B13: =Assumptions!$B$13*Assumptions!$B$7/Assumptions!$B$12 | C13: Shares / 5 x ADR price.
A14: Market value at the Taipei price, US$bn | B14: =Assumptions!$B$13*Assumptions!$B$10/Assumptions!$B$11
A15: Net cash, US$bn (approximate) | B15: =(Assumptions!$B$14-Assumptions!$B$15)/Assumptions!$B$11 | C15: Cash and securities less long-term debt, 30 June 2026.
A16: ADR premium to five Taipei shares | B16: =Assumptions!$B$7/Assumptions!$B$12*Assumptions!$B$11/Assumptions!$B$10-1
A17: ADR change since 30 Sep 2025 | B17: =Assumptions!$B$7/Assumptions!$B$9-1
A18: Price below the 52-week high | B18: =1-Assumptions!$B$7/Assumptions!$B$8
A20: P/E on my 2026E | B20: =Financials!D14
A21: P/E on my 2027E | B21: =Financials!E14
A22: P/E on the 2027 consensus | B22: =Assumptions!$B$7/Assumptions!$B$17 | C22: MarketBeat US$21.33.
A23: P/E on my 2028E | B23: =Financials!F14
A24: My 2027E EPS against consensus | B24: =Financials!E12/Assumptions!$B$17-1
A26: 2028 EPS the price needs at the base multiple, US$ | B26: =Assumptions!$B$7/Assumptions!$B$47 | C26: What the market prices in.
A27: 2028 operating margin that needs, on my 2028E revenue | B27: =B26/(Financials!F5*(1-Assumptions!$B$38)*(Assumptions!$B$12/Assumptions!$B$13))-Assumptions!$B$37 | C27: Against my 55.5%.
A28: 2028 revenue that needs, at my 2028E margin, US$bn | B28: =B26/((Assumptions!$B$46+Assumptions!$B$37)*(1-Assumptions!$B$38)*(Assumptions!$B$12/Assumptions!$B$13)) | C28: Against my US$250.9bn.
A29: 2029 revenue on TSMC's 25% CAGR from 2024, US$bn | B29: =Assumptions!$B$21*(1+Assumptions!$B$32)^5 | C29: TSMC 4Q25 presentation.
A30: Annual growth that leaves for 2027 to 2029 | B30: =(B29/Financials!D5)^(1/3)-1 | C30: My base sits inside this.
A31: Price that puts the base case 16% above | B31: =B7/1.165 | C31: The 'revisit below about US$400' line.

Sheet Scenarios
A1: THREE CASES, TWELVE MONTHS OUT
A2: Tommy Lau | TSMC (NYSE: TSM; TWSE: 2330) | 6 October 2026 | Personal research, not investment advice.
A4: Case | B4: 2027 growth | C4: 2028 growth | D4: 2027 margin | E4: 2028 margin | F4: 2027 revenue | G4: 2028 revenue | H4: 2028 EPS | I4: Multiple | J4: Value, US$ | K4: vs price
A5: Bear | B5: 0.15 | C5: 0.05 | D5: 0.55 | E5: 0.5 | F5: =Financials!$D$5*(1+B5) | G5: =F5*(1+C5) | H5: =G5*(E5+Assumptions!$B$37)*(1-Assumptions!$B$38)*(Assumptions!$B$12/Assumptions!$B$13) | I5: 16 | J5: =H5*I5 | K5: =J5/Assumptions!$B$7-1
A6: Base | B6: =Assumptions!$B$43 | C6: =Assumptions!$B$44 | D6: =Assumptions!$B$45 | E6: =Assumptions!$B$46 | F6: =Financials!$D$5*(1+B6) | G6: =F6*(1+C6) | H6: =G6*(E6+Assumptions!$B$37)*(1-Assumptions!$B$38)*(Assumptions!$B$12/Assumptions!$B$13) | I6: =Assumptions!$B$47 | J6: =H6*I6 | K6: =J6/Assumptions!$B$7-1
A7: Bull | B7: 0.3 | C7: 0.25 | D7: 0.59 | E7: 0.59 | F7: =Financials!$D$5*(1+B7) | G7: =F7*(1+C7) | H7: =G7*(E7+Assumptions!$B$37)*(1-Assumptions!$B$38)*(Assumptions!$B$12/Assumptions!$B$13) | I7: 24 | J7: =H7*I7 | K7: =J7/Assumptions!$B$7-1
B8: Bear | C8: Base | D8: Bull
A9: Probability | B9: 0.25 | C9: 0.5 | D9: 0.25 | E9: =SUM(B9:D9) | F9: must be 100%
A11: Probability-weighted value, US$ | F11: =B9*J5+C9*J6+D9*J7 | G11: =F11/Assumptions!$B$7-1
A14: All cases start from my 2026E revenue and use the same earnings bridge. The 2027 margin affects only 2027 earnings; the value uses 2028.
A15: Bear: the grid binds first and TSMC's tightness eases as 2028 capacity lands. Bull: the factory stays the bottleneck and the scarcity margin holds.

Sheet Sensitivity
A1: VALUE PER ADR: 2028E EPS AGAINST MULTIPLE (US$)
A2: Tommy Lau | TSMC (NYSE: TSM; TWSE: 2330) | 6 October 2026 | Personal research, not investment advice.
A4: 2028 EPS \ multiple | B4: 16 | C4: =Assumptions!$B$47 | D4: 24
A5: 20 | B5: =$A5*B$4 | C5: =$A5*C$4 | D5: =$A5*D$4
A6: =Financials!F12 | B6: =$A6*B$4 | C6: =$A6*C$4 | D6: =$A6*D$4
A7: 26 | B7: =$A7*B$4 | C7: =$A7*C$4 | D7: =$A7*D$4
A9: Cells above the reference price | B9: =COUNTIF(B5:D7,">"&Assumptions!$B$7) | C9: of 9
A11: Middle row links to the model's 2028E EPS and the middle column to the base multiple.

Sheet Peers
A1: PEER MULTIPLES (FORWARD P/E, stockanalysis.com, 6 OCTOBER 2026)
A2: Tommy Lau | TSMC (NYSE: TSM; TWSE: 2330) | 6 October 2026 | Personal research, not investment advice.
A4: Company | B4: Ticker | C4: Forward P/E | D4: What they make
A5: TSMC | B5: NYSE: TSM | C5: =Assumptions!$B$18 | D5: Foundry: makes chips others design; CoWoS advanced packaging
A6: GlobalFoundries | B6: Nasdaq: GFS | C6: 22.42 | D6: Foundry, mature and specialty processes
A7: United Microelectronics | B7: NYSE: UMC | C7: 23.97 | D7: Foundry, mature processes; makes interposers
A8: Intel | B8: Nasdaq: INTC | C8: 68.82 | D8: Designs and makes its own chips; Intel Foundry for outside customers
A9: ASE Technology | B9: NYSE: ASX | C9: 31.41 | D9: Chip packaging and test, including advanced packaging
A10: Samsung Electronics | B10: KRX: 005930 | C10: 4.46 | D10: Memory, including stacked HBM; Samsung Foundry
A11: Nvidia (customer) | B11: Nasdaq: NVDA | C11: 19.75 | D11: Designs AI accelerators; has them made at TSMC
A13: Median of the foundries and ASE (GFS, UMC, ASX) | C13: =MEDIAN(C6,C7,C9)
A15: Intel and Samsung multiples are distorted by recovery and memory cycles. Nvidia is a customer, shown for context.
A16: Multiples only, to set the base multiple. No view on the peers' shares is expressed.

Sheet Sources
A1: SOURCES
A2: Tommy Lau | TSMC (NYSE: TSM; TWSE: 2330) | 6 October 2026 | Personal research, not investment advice.
A4: No. | B4: Source and what it supports
A5: 1 | B5: TSMC quarterly results releases (Exhibit 99.1) and presentations furnished on Form 6-K, 18 April 2024 to 16 July 2026: revenue, margins, EPS, mix, wafers, balance sheet, cash flow, Q3 2026 guide.
A6: 2 | B6: TSMC 4Q25 presentation, 15 January 2026: 2024 and 2025 annual figures; 2024 to 2029 revenue CAGR approaching 25%; long-term gross margin of 56% and higher through the cycle.
A7: 3 | B7: TSMC monthly revenue reports on Form 6-K, 10 February 2025 to 10 September 2026.
A8: 4 | B8: TSMC earnings call transcripts, 15 January 2026 and 16 July 2026: wafer supply, power, Taiwan electricity, fab build time, capex timing and the US$60 to 64bn budget, packaging, overseas and 2nm dilution, Arizona, dividends.
A9: 5 | B9: TSMC Form 6-K, 15 May 2026: sale of up to 8.1% of Vanguard International Semiconductor.
A10: 6 | B10: TSMC investor relations, quarterly results page: Q3 2026 conference on 15 October 2026, 14:00 Taiwan time.
A11: 7 | B11: Yahoo Finance chart API, retrieved 6 October 2026: TSM month-end closes and 5 October close, 52-week range, 2330.TW close, TWD=X.
A12: 8 | B12: MarketBeat, retrieved 6 October 2026: 2026 and 2027 consensus EPS per ADR. stockanalysis.com, retrieved 6 October 2026: forward P/E, analyst target, peer multiples.
A13: 9 | B13: The Physical Layer, 'TSMC's chief says the AI bottleneck is its factories, not the power grid', 2 October 2026: https://thephysicallayer.fyi/journal/tsmc-says-it-is-the-bottleneck/
A14: 10 | B14: Estimates for 2026 to 2028 are the author's own. Personal research, not investment advice. I hold no position in TSMC.
